<?xml version="1.0"?>
<robot name="four_wheel_car" xmlns:xacro="http://ros.org/wiki/xacro">

  <!-- Chassis -->
  <link name="base_link">
    <visual>
      <geometry>
        <box size="0.5 0.3 0.1"/>
      </geometry>
      <material name="pink"/>
    </visual>
    <collision>
      <geometry>
        <box size="0.5 0.3 0.1"/>
      </geometry>
    </collision>
    <inertial>
      <mass value="5.0"/>
      <inertia ixx="0.1" ixy="0.0" ixz="0.0"
               iyy="0.1" iyz="0.0"
               izz="0.1"/>
    </inertial>
  </link>

  <!-- Wheels -->
  <xacro:macro name="wheel" params="name x y z">
    <link name="${name}">
      <visual>
        <geometry>
          <cylinder radius="0.05" length="0.02"/>
        </geometry>
        <material name="pink"/>
      </visual>
      <collision>
        <geometry>
          <cylinder radius="0.05" length="0.02"/>
        </geometry>
      </collision>
      <inertial>
        <mass value="0.2"/>
        <inertia ixx="0.001" ixy="0.0" ixz="0.0"
                 iyy="0.001" iyz="0.0"
                 izz="0.001"/>
      </inertial>
    </link>
    <joint name="${name}_joint" type="continuous">
      <parent link="base_link"/>
      <child link="${name}"/>
      <origin xyz="${x} ${y} ${z}" rpy="0 0 0"/>
      <axis xyz="0 1 0"/>
    </joint>
  </xacro:macro>

  <!-- Four wheels -->
  <xacro:wheel name="front_left_wheel"  x="0.2"  y="0.15" z="-0.05"/>
  <xacro:wheel name="front_right_wheel" x="0.2"  y="-0.15" z="-0.05"/>
  <xacro:wheel name="rear_left_wheel"   x="-0.2" y="0.15" z="-0.05"/>
  <xacro:wheel name="rear_right_wheel"  x="-0.2" y="-0.15" z="-0.05"/>

  <!-- Camera -->
  <link name="camera_link">
    <visual>
      <geometry>
        <box size="0.05 0.05 0.05"/>
      </geometry>
      <material name="grey"/>
    </visual>
  </link>
  <joint name="camera_joint" type="fixed">
    <parent link="base_link"/>
    <child link="camera_link"/>
    <origin xyz="0.15 0 0.1" rpy="0 0 0"/>
  </joint>

</robot>
