<?xml version="1.0"?>
<robot name="four_wheel_car" xmlns:xacro="http://ros.org/wiki/xacro">

  <!-- Materials -->
  <material name="pink">
    <color rgba="1 0.41 0.71 1"/>
  </material>
  <material name="green">
    <color rgba="0 1 0 1"/>
  </material>
  <material name="grey">
    <color rgba="0.5 0.5 0.5 1"/>
  </material>
  <material name="black">
    <color rgba="0 0 0 1"/>
  </material>

  <!-- Chassis -->
  <link name="base_link">
    <visual>
      <geometry>
        <box size="0.5 0.3 0.1"/>
      </geometry>
      <material name="pink"/>
    </visual>
    <collision>
      <geometry>
        <box size="0.5 0.3 0.1"/>
      </geometry>
    </collision>
    <inertial>
      <mass value="5.0"/>
      <inertia ixx="0.1" ixy="0.0" ixz="0.0"
               iyy="0.1" iyz="0.0"
               izz="0.1"/>
    </inertial>
  </link>

  <!-- Front Wheel Macro -->
  <xacro:macro name="front_wheel" params="name x y z">
    <!-- Steering link -->
    <link name="${name}_steering_link">
      <visual>
        <geometry>
          <cylinder radius="0.02" length="0.06"/>
        </geometry>
        <material name="grey"/>
      </visual>
      <collision>
        <geometry>
          <cylinder radius="0.02" length="0.06"/>
        </geometry>
      </collision>
      <inertial>
        <mass value="0.05"/>
        <inertia ixx="0.0001" ixy="0.0" ixz="0.0"
                 iyy="0.0001" iyz="0.0"
                 izz="0.0001"/>
      </inertial>
    </link>

    <!-- Steering joint -->
    <joint name="${name}_steering_joint" type="revolute">
      <parent link="base_link"/>
      <child link="${name}_steering_link"/>
      <origin xyz="${x} ${y} ${z}" rpy="0 0 0"/>
      <axis xyz="0 0 1"/>
      <limit lower="-0.785" upper="0.785" effort="1" velocity="1"/>
    </joint>

    <!-- Wheel link -->
    <link name="${name}">
      <visual>
        <origin rpy="1.5708 0 0" xyz="0 0 0"/>
        <geometry>
          <cylinder radius="0.05" length="0.02"/>
        </geometry>
        <material name="black"/>
      </visual>
      <collision>
        <origin rpy="1.5708 0 0" xyz="0 0 0"/>
        <geometry>
          <cylinder radius="0.05" length="0.02"/>
        </geometry>
      </collision>
      <inertial>
        <mass value="0.2"/>
        <inertia ixx="0.001" ixy="0.0" ixz="0.0"
                 iyy="0.001" iyz="0.0"
                 izz="0.001"/>
      </inertial>
    </link>

    <!-- Wheel joint -->
    <joint name="${name}_joint" type="continuous">
      <parent link="${name}_steering_link"/>
      <child link="${name}"/>
      <origin xyz="0 0 0" rpy="0 0 0"/>
      <axis xyz="0 1 0"/>
    </joint>
  </xacro:macro>

  <!-- Rear Wheel Macro -->
  <xacro:macro name="rear_wheel" params="name x y z">
    <link name="${name}">
      <visual>
        <origin rpy="1.5708 0 0" xyz="0 0 0"/>
        <geometry>
          <cylinder radius="0.05" length="0.02"/>
        </geometry>
        <material name="black"/>
      </visual>
      <collision>
        <origin rpy="1.5708 0 0" xyz="0 0 0"/>
        <geometry>
          <cylinder radius="0.05" length="0.02"/>
        </geometry>
      </collision>
      <inertial>
        <mass value="0.2"/>
        <inertia ixx="0.001" ixy="0.0" ixz="0.0"
                 iyy="0.001" iyz="0.0"
                 izz="0.001"/>
      </inertial>
    </link>

    <joint name="${name}_joint" type="continuous">
      <parent link="base_link"/>
      <child link="${name}"/>
      <origin xyz="${x} ${y} ${z}" rpy="0 0 0"/>
      <axis xyz="0 1 0"/>
    </joint>
  </xacro:macro>

  <!-- Instantiate Wheels -->
  <xacro:front_wheel name="front_left_wheel"  x="0.2"  y="0.15" z="-0.05"/>
  <xacro:front_wheel name="front_right_wheel" x="0.2"  y="-0.15" z="-0.05"/>
  <xacro:rear_wheel name="rear_left_wheel"   x="-0.2" y="0.15" z="-0.05"/>
  <xacro:rear_wheel name="rear_right_wheel"  x="-0.2" y="-0.15" z="-0.05"/>

  <!-- LiDAR -->
  <link name="lidar_link">
    <visual>
      <geometry>
        <cylinder length="0.05" radius="0.05"/>
      </geometry>
      <material name="green"/>
    </visual>
  </link>
  <joint name="lidar_joint" type="fixed">
    <parent link="base_link"/>
    <child link="lidar_link"/>
    <origin xyz="0.0 0 0.15" rpy="0 0 0"/>
  </joint>
  <gazebo reference="lidar_link">
    <sensor name="lidar" type="ray">
      <update_rate>10</update_rate>
      <ray>
        <scan>
          <horizontal>
            <samples>720</samples>
            <resolution>1</resolution>
            <min_angle>-1.57</min_angle>
            <max_angle>1.57</max_angle>
          </horizontal>
        </scan>
        <range>
          <min>0.12</min>
          <max>12.0</max>
          <resolution>0.01</resolution>
        </range>
        <noise>
          <type>gaussian</type>
          <mean>0.0</mean>
          <stddev>0.01</stddev>
        </noise>
      </ray>
      <plugin name="gazebo_ros_laser_controller" filename="libgazebo_ros_ray_sensor.so">
        <ros>
          <remapping>scan:=/scan</remapping>
        </ros>
        <output_type>sensor_msgs/LaserScan</output_type>
      </plugin>
    </sensor>
  </gazebo>

  <!-- Camera -->
  <link name="camera_link">
    <visual>
      <geometry>
        <box size="0.05 0.05 0.05"/>
      </geometry>
      <material name="grey"/>
    </visual>
  </link>
  <joint name="camera_joint" type="fixed">
    <parent link="base_link"/>
    <child link="camera_link"/>
    <origin xyz="0.15 0 0.1" rpy="0 0 0"/>
  </joint>
  <gazebo reference="camera_link">
    <sensor name="camera" type="camera">
      <camera>
        <horizontal_fov>1.047</horizontal_fov>
        <image>
          <width>640</width>
          <height>480</height>
          <format>R8G8B8</format>
        </image>
        <clip>
          <near>0.1</near>
          <far>10.0</far>
        </clip>
      </camera>
      <plugin name="gazebo_ros_camera" filename="libgazebo_ros_camera.so">
        <ros>
          <namespace>/</namespace>
          <remapping>image_raw:=/camera/image_raw</remapping>
          <remapping>camera_info:=/camera/camera_info</remapping>
        </ros>
      </plugin>
    </sensor>
  </gazebo>

  <!-- Differential Drive Plugin -->
  <gazebo>
    <plugin name="diff_drive" filename="libgazebo_ros_diff_drive.so">
      <ros>
        <namespace>/</namespace>
        <remapping>cmd_vel:=/cmd_vel</remapping>
        <remapping>odom:=/odom</remapping>
      </ros>
      <update_rate>50</update_rate>
      <left_joint>rear_left_wheel_joint</left_joint>
      <right_joint>rear_right_wheel_joint</right_joint>
      <wheel_separation>0.3</wheel_separation>
      <wheel_diameter>0.1</wheel_diameter>
      <odom_frame>odom</odom_frame>
      <base_frame>base_link</base_frame>
      <publish_odom>true</publish_odom>
      <publish_odom_tf>true</publish_odom_tf>
    </plugin>
  </gazebo>

</robot>
